<?xml version="1.0"?>
<robot name="my_robot" xmlns:xacro="http://www.ros.org/wiki/xacro">
  <link name="base_link">
    <inertial>
      <mass value="1.0"/>
      <origin xyz="0 0 0" rpy="0 0 0"/>
      <inertia ixx="0.05" ixy="0.0" ixz="0.0" iyy="0.05" iyz="0.0" izz="0.1"/>
    </inertial>
    <visual>
      <origin xyz="0 0 0" rpy="0 0 0"/>
      <geometry>
        <box size="0.5 0.5 0.1"/>
      </geometry>
    </visual>
    <collision>
      <origin xyz="0 0 0" rpy="0 0 0"/>
      <geometry>
        <box size="0.5 0.5 0.1"/>
      </geometry>
    </collision>
  </link>

  <joint name="left_wheel_joint" type="continuous">
    <origin xyz="0 -0.25 0.0" rpy="0 0 0"/>
    <parent link="base_link"/>
    <child link="left_wheel"/>
    <axis xyz="0 1 0"/>
  </joint>

  <link name="left_wheel">
    <inertial>
      <mass value="0.1"/>
      <origin xyz="0 0 0" rpy="0 0 0"/>
      <inertia ixx="0.001" ixy="0.0" ixz="0.0" iyy="0.002" iyz="0.0" izz="0.001"/>
    </inertial>
    <visual>
      <origin xyz="0.0 0.0 0.0" rpy="0 0 0"/>
      <geometry>
        <cylinder radius="0.05" length="0.1"/>
      </geometry>
    </visual>
    <collision>
      <origin xyz="0.0 0.0 0.0" rpy="0 0 0"/>
      <geometry>
        <cylinder radius="0.05" length="0.1"/>
      </geometry>
    </collision>
  </link>

  <joint name="right_wheel_joint" type="continuous">
    <origin xyz="0 0.25 0.0" rpy="0 0 0"/>
    <parent link="base_link"/>
    <child link="right_wheel"/>
    <axis xyz="0 1 0"/>
  </joint>

  <link name="right_wheel">
    <inertial>
      <mass value="0.1"/>
      <origin xyz="0 0 0" rpy="0 0 0"/>
      <inertia ixx="0.001" ixy="0.0" ixz="0.0" iyy="0.002" iyz="0.0" izz="0.001"/>
    </inertial>
    <visual>
      <origin xyz="0.0 0.0 0.0" rpy="0 0 0"/>
      <geometry>
        <cylinder radius="0.05" length="0.1"/>
      </geometry>
    </visual>
    <collision>
      <origin xyz="0.0 0.0 0.0" rpy="0 0 0"/>
      <geometry>
        <cylinder radius="0.05" length="0.1"/>
      </geometry>
    </collision>
  </link>

  <link name="camera_link">
    <inertial>
      <mass value="0.1"/>
      <origin xyz="0 0 0" rpy="0 0 0"/>
      <inertia ixx="0.001" ixy="0.0" ixz="0.0" iyy="0.001" iyz="0.0" izz="0.001"/>
    </inertial>
    <visual>
      <origin xyz="0.0 0.0 0.0" rpy="0 0 0"/>
      <geometry>
        <box size="0.2 0.2 0.2"/>
      </geometry>
    </visual>
    <collision>
      <origin xyz="0.0 0.0 0.0" rpy="0 0 0"/>
      <geometry>
        <box size="0.2 0.2 0.2"/>
      </geometry>
    </collision>
  </link>

  <joint name="camera_joint" type="fixed">
    <origin xyz="0.0 0.0 0.1" rpy="0 0 0"/>
    <parent link="base_link"/>
    <child link="camera_link"/>
  </joint>

  <gazebo>
    <plugin name="gazebo_ros_imu" filename="libgazebo_ros_imu.so">
      <robotNamespace>/imu</robotNamespace>
      <imuSensorName>imu_sensor</imuSensorName>
      <frameName>imu_link</frameName>
      <topicName>data_raw</topicName>
      <serviceName>reset</serviceName>
      <gaussianNoise>0.0</gaussianNoise>
      <xyzOffset>0 0 0</xyzOffset>
      <rpyOffset>0 0 0</rpyOffset>
      <alwaysOn>true</alwaysOn>
      <updateRate>50.0</updateRate>
      <imuConfig>1 0 0   0 1 0   0 0 1</imuConfig>
    </plugin>

    <plugin name="gazebo_ros_kinect" filename="libgazebo_ros_openni_kinect.so">
      <alwaysOn>true</alwaysOn>
      <updateRate>30.0</updateRate>
      <cameraName>kinect</cameraName>
      <imageTopicName>image</imageTopicName>
      <depthImageTopicName>depth/image_raw</depthImageTopicName>
      <cameraInfoTopicName>camera_info</cameraInfoTopicName>
      <depthCameraInfoTopicName>depth/camera_info</depthCameraInfoTopicName>
      <pointCloudTopicName>depth/points</pointCloudTopicName>
      <frameName>camera_link</frameName>
      <hackBaseline>0.075</hackBaseline>
      <distortionK1>0.0</distortionK1>
      <distortionK2>0.0</distortionK2>
      <distortionK3>0.0</distortionK3>
      <distortionT1>0.0</distortionT1>
      <distortionT
2>0.0</distortionT2>
      <CxPrime>0.0</CxPrime>
      <Cx>0.0</Cx>
      <Cy>0.0</Cy>
      <focalLength>525.0</focalLength>
      <hackBaseline>0.075</hackBaseline>
      <pointCloudCutoff>0.1</pointCloudCutoff>
      <pointCloudCutoffMax>4.0</pointCloudCutoffMax>
      <pointCloudColorOffset>0</pointCloudColorOffset>
      <pointCloudColorStep>1</pointCloudColorStep>
    </plugin>
  </gazebo>

  <gazebo reference="left_wheel">
    <mu1>10</mu1>
    <mu2>10</mu2>
    <kp>1000000</kp>
    <kd>100</kd>
    <material>Gazebo/Black</material>
  </gazebo>

  <gazebo reference="right_wheel">
    <mu1>10</mu1>
    <mu2>10</mu2>
    <kp>1000000</kp>
    <kd>100</kd>
    <material>Gazebo/Black</material>
  </gazebo>

  <gazebo reference="camera_link">
    <visual name="visual">
      <geometry>
        <box size="0.2 0.2 0.2"/>
      </geometry>
      <material>
        <script>
          <uri>file://media/materials/scripts/gazebo.material</uri>
          <name>Gazebo/Yellow</name>
        </script>
      </material>
    </visual>
    <sensor name="depth_sensor" type="depth">
      <update_rate>30.0</update_rate>
      <visualize>true</visualize>
      <camera name="depth_camera">
        <horizontal_fov>1.047</horizontal_fov>
        <image>
          <width>640</width>
          <height>480</height>
          <format>R8G8B8</format>
        </image>
        <clip>
          <near>0.1</near>
          <far>1000</far>
        </clip>
        <noise>
          <type>gaussian</type>
          <mean>0.0</mean>
          <stddev>0.001</stddev>
        </noise>
      </camera>
      <plugin name="camera_controller" filename="libgazebo_ros_openni_kinect.so">
        <alwaysOn>true</alwaysOn>
        <updateRate>0.0</updateRate>
        <cameraName>kinect</cameraName>
        <imageTopicName>image_raw</imageTopicName>
        <cameraInfoTopicName>camera_info</cameraInfoTopicName>
        <pointCloudTopicName>points</pointCloudTopicName>
        <frameName>camera_link</frameName>
        <CxPrime>0.0</CxPrime>
        <Cx>0.0</Cx>
        <Cy>0.0</Cy>
        <focalLength>525.0</focalLength>
        <hackBaseline>0.075</hackBaseline>
        <distortionK1>0.0</distortionK1>
        <distortionK2>0.0</distortionK2>
        <distortionK3>0.0</distortionK3>
        <distortionT1>0.0</distortionT
1>1.0</distortionT2>
        <pointCloudCutoff>0.1</pointCloudCutoff>
        <pointCloudCutoffMax>4.0</pointCloudCutoffMax>
        <pointCloudColorOffset>0</pointCloudColorOffset>
        <pointCloudColorStep>1</pointCloudColorStep>
      </plugin>
    </sensor>
  </gazebo>

</robot>
